<sdf version='1.11'>
  <model name='mir'>
    <link name='base_footprint'>
      <inertial>
        <pose>-0.010455101563880241 0 0.1517968301110581 0 0 0</pose>
        <mass>65.209753901900001</mass>
        <inertia>
          <ixx>0.82760609330043278</ixx>
          <ixy>-0.22187173998755999</ixy>
          <ixz>-0.0050954005185053766</ixz>
          <iyy>1.9022144420734319</iyy>
          <iyz>7.9516823838238092e-21</iyz>
          <izz>2.2887915511694299</izz>
        </inertia>
      </inertial>
      <collision name='base_footprint_fixed_joint_lump__base_link_collision'>
        <pose>-0.39000000000000001 0.27500000000000002 0.34875 0 0 0</pose>
        <geometry>
          <mesh>
            <scale>1 1 1</scale>
            <uri>model://mir_description/meshes/mir_100/collision/base.stl</uri>
          </mesh>
        </geometry>
      </collision>
      <visual name='base_footprint_fixed_joint_lump__base_link_visual'>
        <pose>-0.39000000000000001 0.27500000000000002 0.34875 0 0 0</pose>
        <geometry>
          <mesh>
            <scale>1 1 1</scale>
            <uri>model://mir_description/meshes/mir_100/visual/base.dae</uri>
          </mesh>
        </geometry>
      </visual>
      <visual name='base_footprint_fixed_joint_lump__back_laser_link_visual_1'>
        <pose>-0.38970933905932748 0.27331688245431418 0.34689999999999999 0 0 0</pose>
        <geometry>
          <mesh>
            <scale>1 1 1</scale>
            <uri>model://mir_description/meshes/mir_100/visual/SICK-lidar.dae</uri>
          </mesh>
        </geometry>
      </visual>
      <visual name='base_footprint_fixed_joint_lump__front_laser_link_visual_2'>
        <pose>0.46500133905932739 -0.27331688245431418 0.34689999999999999 0 0 3.1415926535897931</pose>
        <geometry>
          <mesh>
            <scale>1 1 1</scale>
            <uri>model://mir_description/meshes/mir_100/visual/SICK-lidar.dae</uri>
          </mesh>
        </geometry>
      </visual>
      <sensor name='imu_sensor' type='imu'>
        <always_on>true</always_on>
        <update_rate>50</update_rate>
        <imu>
          <enable_orientation>false</enable_orientation>
          <angular_velocity>
            <x>
              <noise type='gaussian'>
                <mean>0</mean>
                <stddev>0.0089999999999999993</stddev>
                <bias_mean>0.00075000000000000002</bias_mean>
                <bias_stddev>0.0050000000000000001</bias_stddev>
                <dynamic_bias_stddev>2.0000000000000002e-05</dynamic_bias_stddev>
                <dynamic_bias_correlation_time>400</dynamic_bias_correlation_time>
                <precision>0.00025000000000000001</precision>
              </noise>
            </x>
            <y>
              <noise type='gaussian'>
                <mean>0</mean>
                <stddev>0.0089999999999999993</stddev>
                <bias_mean>0.00075000000000000002</bias_mean>
                <bias_stddev>0.0050000000000000001</bias_stddev>
                <dynamic_bias_stddev>2.0000000000000002e-05</dynamic_bias_stddev>
                <dynamic_bias_correlation_time>400</dynamic_bias_correlation_time>
                <precision>0.00025000000000000001</precision>
              </noise>
            </y>
            <z>
              <noise type='gaussian'>
                <mean>0</mean>
                <stddev>0.0089999999999999993</stddev>
                <bias_mean>0.00075000000000000002</bias_mean>
                <bias_stddev>0.0050000000000000001</bias_stddev>
                <dynamic_bias_stddev>2.0000000000000002e-05</dynamic_bias_stddev>
                <dynamic_bias_correlation_time>400</dynamic_bias_correlation_time>
                <precision>0.00025000000000000001</precision>
              </noise>
            </z>
          </angular_velocity>
          <linear_acceleration>
            <x>
              <noise type='gaussian'>
                <mean>0</mean>
                <stddev>0.021000000000000001</stddev>
                <bias_mean>0.050000000000000003</bias_mean>
                <bias_stddev>0.0074999999999999997</bias_stddev>
                <dynamic_bias_stddev>0.00037500000000000001</dynamic_bias_stddev>
                <dynamic_bias_correlation_time>175</dynamic_bias_correlation_time>
                <precision>0.0050000000000000001</precision>
              </noise>
            </x>
            <y>
              <noise type='gaussian'>
                <mean>0</mean>
                <stddev>0.021000000000000001</stddev>
                <bias_mean>0.050000000000000003</bias_mean>
                <bias_stddev>0.0074999999999999997</bias_stddev>
                <dynamic_bias_stddev>0.00037500000000000001</dynamic_bias_stddev>
                <dynamic_bias_correlation_time>175</dynamic_bias_correlation_time>
                <precision>0.0050000000000000001</precision>
              </noise>
            </y>
            <z>
              <noise type='gaussian'>
                <mean>0</mean>
                <stddev>0.021000000000000001</stddev>
                <bias_mean>0.050000000000000003</bias_mean>
                <bias_stddev>0.0074999999999999997</bias_stddev>
                <dynamic_bias_stddev>0.00037500000000000001</dynamic_bias_stddev>
                <dynamic_bias_correlation_time>175</dynamic_bias_correlation_time>
                <precision>0.0050000000000000001</precision>
              </noise>
            </z>
          </linear_acceleration>
        </imu>
        <pose>0 0 0.25 0 0 0</pose>
      </sensor>
    </link>
    <joint name='bl_caster_rotation_joint' type='revolute'>
      <pose relative_to='base_footprint'>-0.27015400000000001 0.20300000000000001 0.1565 0 0 0</pose>
      <parent>base_footprint</parent>
      <child>bl_caster_rotation_link</child>
      <axis>
        <xyz>0 0 1</xyz>
        <limit>
          <lower>-inf</lower>
          <upper>inf</upper>
        </limit>
        <dynamics>
          <damping>0.01</damping>
          <friction>0</friction>
          <spring_reference>0</spring_reference>
          <spring_stiffness>0</spring_stiffness>
        </dynamics>
      </axis>
    </joint>
    <link name='bl_caster_rotation_link'>
      <pose relative_to='bl_caster_rotation_joint'>0 0 0 0 0 0</pose>
      <inertial>
        <pose>0 0 -0.042500000044000001 0.41887902047863912 -2.7755575615628914e-17 1.5707963267948972</pose>
        <mass>0.30975390190000002</mass>
        <inertia>
          <ixx>0.00058445179780000005</ixx>
          <ixy>0</ixy>
          <ixz>0</ixz>
          <iyy>0.00052872551237000001</iyy>
          <iyz>0</iyz>
          <izz>0.00017923555073999999</izz>
        </inertia>
      </inertial>
      <visual name='bl_caster_rotation_link_visual'>
        <pose>-0.12 0.070000000000000007 0.20200000000000001 0 0 0</pose>
        <geometry>
          <mesh>
            <scale>1 1 1</scale>
            <uri>model://mir_description/meshes/mir_100/visual/caster-wheel-base.dae</uri>
          </mesh>
        </geometry>
      </visual>
    </link>
    <joint name='bl_caster_wheel_joint' type='revolute'>
      <pose relative_to='bl_caster_rotation_link'>-0.038199999999999998 0 -0.094 0 0 0</pose>
      <parent>bl_caster_rotation_link</parent>
      <child>bl_caster_wheel_link</child>
      <axis>
        <xyz>0 1 0</xyz>
        <limit>
          <lower>-inf</lower>
          <upper>inf</upper>
        </limit>
        <dynamics>
          <spring_reference>0</spring_reference>
          <spring_stiffness>0</spring_stiffness>
        </dynamics>
      </axis>
    </joint>
    <link name='bl_caster_wheel_link'>
      <pose relative_to='bl_caster_wheel_joint'>0 0 0 0 0 0</pose>
      <inertial>
        <pose>0 0 0 1.5707963267948959 0 0</pose>
        <mass>1</mass>
        <inertia>
          <ixx>0.001061895408575</ixx>
          <ixy>0</ixy>
          <ixz>0</ixz>
          <iyy>0.001061895408575</iyy>
          <iyz>0</iyz>
          <izz>0.001953125</izz>
        </inertia>
      </inertial>
      <collision name='bl_caster_wheel_link_collision'>
        <pose>0 0 0 1.5707963267948959 0 0</pose>
        <geometry>
          <cylinder>
            <length>0.032000000000000001</length>
            <radius>0.0625</radius>
          </cylinder>
        </geometry>
        <surface>
          <contact>
            <ode>
              <kp>10000000</kp>
              <kd>1</kd>
              <min_depth>0.01</min_depth>
            </ode>
          </contact>
          <friction>
            <ode>
              <mu>1</mu>
              <mu2>1</mu2>
            </ode>
          </friction>
        </surface>
      </collision>
      <visual name='bl_caster_wheel_link_visual'>
        <pose>-0.082000000000000003 0.47999999999999998 0.28749999999999998 0 0 0</pose>
        <geometry>
          <mesh>
            <scale>1 1 1</scale>
            <uri>model://mir_description/meshes/mir_100/visual/caster-wheel.dae</uri>
          </mesh>
        </geometry>
      </visual>
    </link>
    <joint name='br_caster_rotation_joint' type='revolute'>
      <pose relative_to='base_footprint'>-0.27015400000000001 -0.20300000000000001 0.1565 0 0 0</pose>
      <parent>base_footprint</parent>
      <child>br_caster_rotation_link</child>
      <axis>
        <xyz>0 0 1</xyz>
        <limit>
          <lower>-inf</lower>
          <upper>inf</upper>
        </limit>
        <dynamics>
          <damping>0.01</damping>
          <friction>0</friction>
          <spring_reference>0</spring_reference>
          <spring_stiffness>0</spring_stiffness>
        </dynamics>
      </axis>
    </joint>
    <link name='br_caster_rotation_link'>
      <pose relative_to='br_caster_rotation_joint'>0 0 0 0 0 0</pose>
      <inertial>
        <pose>0 0 -0.042500000044000001 0.41887902047863912 -2.7755575615628914e-17 1.5707963267948972</pose>
        <mass>0.30975390190000002</mass>
        <inertia>
          <ixx>0.00058445179780000005</ixx>
          <ixy>0</ixy>
          <ixz>0</ixz>
          <iyy>0.00052872551237000001</iyy>
          <iyz>0</iyz>
          <izz>0.00017923555073999999</izz>
        </inertia>
      </inertial>
      <visual name='br_caster_rotation_link_visual'>
        <pose>-0.12 0.070000000000000007 0.20200000000000001 0 0 0</pose>
        <geometry>
          <mesh>
            <scale>1 1 1</scale>
            <uri>model://mir_description/meshes/mir_100/visual/caster-wheel-base.dae</uri>
          </mesh>
        </geometry>
      </visual>
    </link>
    <joint name='br_caster_wheel_joint' type='revolute'>
      <pose relative_to='br_caster_rotation_link'>-0.038199999999999998 0 -0.094 0 0 0</pose>
      <parent>br_caster_rotation_link</parent>
      <child>br_caster_wheel_link</child>
      <axis>
        <xyz>0 1 0</xyz>
        <limit>
          <lower>-inf</lower>
          <upper>inf</upper>
        </limit>
        <dynamics>
          <spring_reference>0</spring_reference>
          <spring_stiffness>0</spring_stiffness>
        </dynamics>
      </axis>
    </joint>
    <link name='br_caster_wheel_link'>
      <pose relative_to='br_caster_wheel_joint'>0 0 0 0 0 0</pose>
      <inertial>
        <pose>0 0 0 1.5707963267948959 0 0</pose>
        <mass>1</mass>
        <inertia>
          <ixx>0.001061895408575</ixx>
          <ixy>0</ixy>
          <ixz>0</ixz>
          <iyy>0.001061895408575</iyy>
          <iyz>0</iyz>
          <izz>0.001953125</izz>
        </inertia>
      </inertial>
      <collision name='br_caster_wheel_link_collision'>
        <pose>0 0 0 1.5707963267948959 0 0</pose>
        <geometry>
          <cylinder>
            <length>0.032000000000000001</length>
            <radius>0.0625</radius>
          </cylinder>
        </geometry>
        <surface>
          <contact>
            <ode>
              <kp>10000000</kp>
              <kd>1</kd>
              <min_depth>0.01</min_depth>
            </ode>
          </contact>
          <friction>
            <ode>
              <mu>1</mu>
              <mu2>1</mu2>
            </ode>
          </friction>
        </surface>
      </collision>
      <visual name='br_caster_wheel_link_visual'>
        <pose>-0.082000000000000003 0.47999999999999998 0.28749999999999998 0 0 0</pose>
        <geometry>
          <mesh>
            <scale>1 1 1</scale>
            <uri>model://mir_description/meshes/mir_100/visual/caster-wheel.dae</uri>
          </mesh>
        </geometry>
      </visual>
    </link>
    <joint name='fl_caster_rotation_joint' type='revolute'>
      <pose relative_to='base_footprint'>0.34134599999999998 0.20300000000000001 0.1565 0 0 0</pose>
      <parent>base_footprint</parent>
      <child>fl_caster_rotation_link</child>
      <axis>
        <xyz>0 0 1</xyz>
        <limit>
          <lower>-inf</lower>
          <upper>inf</upper>
        </limit>
        <dynamics>
          <damping>0.01</damping>
          <friction>0</friction>
          <spring_reference>0</spring_reference>
          <spring_stiffness>0</spring_stiffness>
        </dynamics>
      </axis>
    </joint>
    <link name='fl_caster_rotation_link'>
      <pose relative_to='fl_caster_rotation_joint'>0 0 0 0 0 0</pose>
      <inertial>
        <pose>0 0 -0.042500000044000001 0.41887902047863912 -2.7755575615628914e-17 1.5707963267948972</pose>
        <mass>0.30975390190000002</mass>
        <inertia>
          <ixx>0.00058445179780000005</ixx>
          <ixy>0</ixy>
          <ixz>0</ixz>
          <iyy>0.00052872551237000001</iyy>
          <iyz>0</iyz>
          <izz>0.00017923555073999999</izz>
        </inertia>
      </inertial>
      <visual name='fl_caster_rotation_link_visual'>
        <pose>-0.12 0.070000000000000007 0.20200000000000001 0 0 0</pose>
        <geometry>
          <mesh>
            <scale>1 1 1</scale>
            <uri>model://mir_description/meshes/mir_100/visual/caster-wheel-base.dae</uri>
          </mesh>
        </geometry>
      </visual>
    </link>
    <joint name='fl_caster_wheel_joint' type='revolute'>
      <pose relative_to='fl_caster_rotation_link'>-0.038199999999999998 0 -0.094 0 0 0</pose>
      <parent>fl_caster_rotation_link</parent>
      <child>fl_caster_wheel_link</child>
      <axis>
        <xyz>0 1 0</xyz>
        <limit>
          <lower>-inf</lower>
          <upper>inf</upper>
        </limit>
        <dynamics>
          <spring_reference>0</spring_reference>
          <spring_stiffness>0</spring_stiffness>
        </dynamics>
      </axis>
    </joint>
    <link name='fl_caster_wheel_link'>
      <pose relative_to='fl_caster_wheel_joint'>0 0 0 0 0 0</pose>
      <inertial>
        <pose>0 0 0 1.5707963267948959 0 0</pose>
        <mass>1</mass>
        <inertia>
          <ixx>0.001061895408575</ixx>
          <ixy>0</ixy>
          <ixz>0</ixz>
          <iyy>0.001061895408575</iyy>
          <iyz>0</iyz>
          <izz>0.001953125</izz>
        </inertia>
      </inertial>
      <collision name='fl_caster_wheel_link_collision'>
        <pose>0 0 0 1.5707963267948959 0 0</pose>
        <geometry>
          <cylinder>
            <length>0.032000000000000001</length>
            <radius>0.0625</radius>
          </cylinder>
        </geometry>
        <surface>
          <contact>
            <ode>
              <kp>10000000</kp>
              <kd>1</kd>
              <min_depth>0.01</min_depth>
            </ode>
          </contact>
          <friction>
            <ode>
              <mu>1</mu>
              <mu2>1</mu2>
            </ode>
          </friction>
        </surface>
      </collision>
      <visual name='fl_caster_wheel_link_visual'>
        <pose>-0.082000000000000003 0.47999999999999998 0.28749999999999998 0 0 0</pose>
        <geometry>
          <mesh>
            <scale>1 1 1</scale>
            <uri>model://mir_description/meshes/mir_100/visual/caster-wheel.dae</uri>
          </mesh>
        </geometry>
      </visual>
    </link>
    <joint name='fr_caster_rotation_joint' type='revolute'>
      <pose relative_to='base_footprint'>0.34134599999999998 -0.20300000000000001 0.1565 0 0 0</pose>
      <parent>base_footprint</parent>
      <child>fr_caster_rotation_link</child>
      <axis>
        <xyz>0 0 1</xyz>
        <limit>
          <lower>-inf</lower>
          <upper>inf</upper>
        </limit>
        <dynamics>
          <damping>0.01</damping>
          <friction>0</friction>
          <spring_reference>0</spring_reference>
          <spring_stiffness>0</spring_stiffness>
        </dynamics>
      </axis>
    </joint>
    <link name='fr_caster_rotation_link'>
      <pose relative_to='fr_caster_rotation_joint'>0 0 0 0 0 0</pose>
      <inertial>
        <pose>0 0 -0.042500000044000001 0.41887902047863912 -2.7755575615628914e-17 1.5707963267948972</pose>
        <mass>0.30975390190000002</mass>
        <inertia>
          <ixx>0.00058445179780000005</ixx>
          <ixy>0</ixy>
          <ixz>0</ixz>
          <iyy>0.00052872551237000001</iyy>
          <iyz>0</iyz>
          <izz>0.00017923555073999999</izz>
        </inertia>
      </inertial>
      <visual name='fr_caster_rotation_link_visual'>
        <pose>-0.12 0.070000000000000007 0.20200000000000001 0 0 0</pose>
        <geometry>
          <mesh>
            <scale>1 1 1</scale>
            <uri>model://mir_description/meshes/mir_100/visual/caster-wheel-base.dae</uri>
          </mesh>
        </geometry>
      </visual>
    </link>
    <joint name='fr_caster_wheel_joint' type='revolute'>
      <pose relative_to='fr_caster_rotation_link'>-0.038199999999999998 0 -0.094 0 0 0</pose>
      <parent>fr_caster_rotation_link</parent>
      <child>fr_caster_wheel_link</child>
      <axis>
        <xyz>0 1 0</xyz>
        <limit>
          <lower>-inf</lower>
          <upper>inf</upper>
        </limit>
        <dynamics>
          <spring_reference>0</spring_reference>
          <spring_stiffness>0</spring_stiffness>
        </dynamics>
      </axis>
    </joint>
    <link name='fr_caster_wheel_link'>
      <pose relative_to='fr_caster_wheel_joint'>0 0 0 0 0 0</pose>
      <inertial>
        <pose>0 0 0 1.5707963267948959 0 0</pose>
        <mass>1</mass>
        <inertia>
          <ixx>0.001061895408575</ixx>
          <ixy>0</ixy>
          <ixz>0</ixz>
          <iyy>0.001061895408575</iyy>
          <iyz>0</iyz>
          <izz>0.001953125</izz>
        </inertia>
      </inertial>
      <collision name='fr_caster_wheel_link_collision'>
        <pose>0 0 0 1.5707963267948959 0 0</pose>
        <geometry>
          <cylinder>
            <length>0.032000000000000001</length>
            <radius>0.0625</radius>
          </cylinder>
        </geometry>
        <surface>
          <contact>
            <ode>
              <kp>10000000</kp>
              <kd>1</kd>
              <min_depth>0.01</min_depth>
            </ode>
          </contact>
          <friction>
            <ode>
              <mu>1</mu>
              <mu2>1</mu2>
            </ode>
          </friction>
        </surface>
      </collision>
      <visual name='fr_caster_wheel_link_visual'>
        <pose>-0.082000000000000003 0.47999999999999998 0.28749999999999998 0 0 0</pose>
        <geometry>
          <mesh>
            <scale>1 1 1</scale>
            <uri>model://mir_description/meshes/mir_100/visual/caster-wheel.dae</uri>
          </mesh>
        </geometry>
      </visual>
    </link>
    <joint name='left_wheel_joint' type='revolute'>
      <pose relative_to='base_footprint'>0 0.222604 0.0625 0 0 0</pose>
      <parent>base_footprint</parent>
      <child>left_wheel_link</child>
      <axis>
        <xyz>0 1 0</xyz>
        <limit>
          <effort>100</effort>
          <velocity>20</velocity>
          <lower>-inf</lower>
          <upper>inf</upper>
        </limit>
        <dynamics>
          <spring_reference>0</spring_reference>
          <spring_stiffness>0</spring_stiffness>
        </dynamics>
      </axis>
    </joint>
    <link name='left_wheel_link'>
      <pose relative_to='left_wheel_joint'>0 0 0 0 0 0</pose>
      <inertial>
        <pose>0 0 0 1.5707963267948959 0 0</pose>
        <mass>1</mass>
        <inertia>
          <ixx>0.001061895408575</ixx>
          <ixy>0</ixy>
          <ixz>0</ixz>
          <iyy>0.001061895408575</iyy>
          <iyz>0</iyz>
          <izz>0.001953125</izz>
        </inertia>
      </inertial>
      <collision name='left_wheel_link_collision'>
        <pose>0 0 0 1.5707963267948959 0 0</pose>
        <geometry>
          <cylinder>
            <length>0.032000000000000001</length>
            <radius>0.0625</radius>
          </cylinder>
        </geometry>
        <surface>
          <contact>
            <ode>
              <kp>10000000</kp>
              <kd>1</kd>
              <min_depth>0.01</min_depth>
            </ode>
          </contact>
          <friction>
            <ode>
              <mu>200</mu>
              <mu2>200</mu2>
            </ode>
          </friction>
        </surface>
      </collision>
      <visual name='left_wheel_link_visual'>
        <pose>-0.026200000000000001 -0.42958299999999999 0.42299999999999999 0 0 -3.1415926535897931</pose>
        <geometry>
          <mesh>
            <scale>1 1 1</scale>
            <uri>model://mir_description/meshes/mir_100/visual/wheel.dae</uri>
          </mesh>
        </geometry>
      </visual>
    </link>
    <joint name='right_wheel_joint' type='revolute'>
      <pose relative_to='base_footprint'>0 -0.222604 0.0625 0 0 0</pose>
      <parent>base_footprint</parent>
      <child>right_wheel_link</child>
      <axis>
        <xyz>0 1 0</xyz>
        <limit>
          <effort>100</effort>
          <velocity>20</velocity>
          <lower>-inf</lower>
          <upper>inf</upper>
        </limit>
        <dynamics>
          <spring_reference>0</spring_reference>
          <spring_stiffness>0</spring_stiffness>
        </dynamics>
      </axis>
    </joint>
    <link name='right_wheel_link'>
      <pose relative_to='right_wheel_joint'>0 0 0 0 0 0</pose>
      <inertial>
        <pose>0 0 0 1.5707963267948959 0 0</pose>
        <mass>1</mass>
        <inertia>
          <ixx>0.001061895408575</ixx>
          <ixy>0</ixy>
          <ixz>0</ixz>
          <iyy>0.001061895408575</iyy>
          <iyz>0</iyz>
          <izz>0.001953125</izz>
        </inertia>
      </inertial>
      <collision name='right_wheel_link_collision'>
        <pose>0 0 0 1.5707963267948959 0 0</pose>
        <geometry>
          <cylinder>
            <length>0.032000000000000001</length>
            <radius>0.0625</radius>
          </cylinder>
        </geometry>
        <surface>
          <contact>
            <ode>
              <kp>10000000</kp>
              <kd>1</kd>
              <min_depth>0.01</min_depth>
            </ode>
          </contact>
          <friction>
            <ode>
              <mu>200</mu>
              <mu2>200</mu2>
            </ode>
          </friction>
        </surface>
      </collision>
      <visual name='right_wheel_link_visual'>
        <pose>0.026200000000000001 0.42958299999999999 0.42299999999999999 0 0 0</pose>
        <geometry>
          <mesh>
            <scale>1 1 1</scale>
            <uri>model://mir_description/meshes/mir_100/visual/wheel.dae</uri>
          </mesh>
        </geometry>
      </visual>
    </link>
    <plugin name='gz_ros2_control::GazeboSimROS2ControlPlugin' filename='gz_ros2_control-system'>
      <parameters>/home/ubuntu/workspace/install/mir_description/share/mir_description/config/diff_drive_controller_velocity.yaml</parameters>
      <controller_manager_name>mir_controller_manager</controller_manager_name>
      <ros>
        <namespace/>
        <remapping>/robot_description:=/robot_description</remapping>
      </ros>
    </plugin>
    <plugin name='gz::sim::systems::Sensors' filename='gz-sim-sensors-system'>
      <render_engine>ogre2</render_engine>
    </plugin>
    <plugin name='gz::sim::systems::Imu' filename='gz-sim-imu-system'/>
    <frame name='base_link_surface_joint' attached_to='base_link'>
      <pose>0.037645999999999999 0 0.35199999999999998 0 0 0</pose>
    </frame>
    <frame name='surface' attached_to='base_link_surface_joint'>
      <pose>0 0 0 0 0 0</pose>
    </frame>
    <frame name='base_link_to_back_laser_joint' attached_to='base_link'>
      <pose>-0.354354 -0.23580000000000001 0.19139999999999999 0 0 -2.3561944901923448</pose>
    </frame>
    <frame name='back_laser_link' attached_to='base_link_to_back_laser_joint'>
      <pose>0 0 0 0 0 0</pose>
    </frame>
    <frame name='base_link_to_front_laser_joint' attached_to='base_link'>
      <pose>0.42964599999999997 0.23580000000000001 0.19139999999999999 0 0 0.78539816339744839</pose>
    </frame>
    <frame name='front_laser_link' attached_to='base_link_to_front_laser_joint'>
      <pose>0 0 0 0 0 0</pose>
    </frame>
    <frame name='imu_link_to_imu_frame_joint' attached_to='imu_link'>
      <pose>0 0 0 0 0 0</pose>
    </frame>
    <frame name='imu_frame' attached_to='imu_link_to_imu_frame_joint'>
      <pose>0 0 0 0 0 0</pose>
    </frame>
    <frame name='base_link_to_imu_joint' attached_to='base_link'>
      <pose>0 0 0.25 0 0 0</pose>
    </frame>
    <frame name='imu_link' attached_to='base_link_to_imu_joint'>
      <pose>0 0 0 0 0 0</pose>
    </frame>
    <frame name='us_1_joint' attached_to='base_link'>
      <pose>0.45000000000000001 -0.12 0.16 0 0 0</pose>
    </frame>
    <frame name='us_1_frame' attached_to='us_1_joint'>
      <pose>0 0 0 0 0 0</pose>
    </frame>
    <frame name='us_2_joint' attached_to='base_link'>
      <pose>0.45000000000000001 0.12 0.16 0 0 0</pose>
    </frame>
    <frame name='us_2_frame' attached_to='us_2_joint'>
      <pose>0 0 0 0 0 0</pose>
    </frame>
    <frame name='base_joint' attached_to='base_footprint'>
      <pose>0 0 0 0 0 0</pose>
    </frame>
    <frame name='base_link' attached_to='base_joint'>
      <pose>0 0 0 0 0 0</pose>
    </frame>
  </model>
</sdf>
