<sdf version='1.11'>
  <model name='mir'>
    <link name='base_footprint'>
      <inertial>
        <pose>-0.0094893931925710846 2.5915397656292678e-06 0.15142383800162071 0 0 0</pose>
        <mass>65.043999999999997</mass>
        <inertia>
          <ixx>0.83460955065946574</ixx>
          <ixy>-0.22193205415256359</ixy>
          <ixz>-0.00047938575414187279</ixz>
          <iyy>1.938333749197118</iyy>
          <iyz>-2.9538236075815811e-05</iyz>
          <izz>2.3211475522814178</izz>
        </inertia>
      </inertial>
      <collision name='base_footprint_fixed_joint_lump__base_link_collision'>
        <pose>-0.39000000000000001 0.27500000000000002 0.34875 0 0 0</pose>
        <geometry>
          <mesh>
            <scale>1 1 1</scale>
            <uri>model://mir_description/meshes/mir_100/collision/base.stl</uri>
          </mesh>
        </geometry>
      </collision>
      <collision name='base_footprint_fixed_joint_lump__camera1_link_collision_1'>
        <pose>0.4453526696328326 0.068559666353336102 0.1187433129193733 -1.762350117219587 -0.31852716257095287 -0.49273867058666515</pose>
        <geometry>
          <box>
            <size>0.025049999999999999 0.089999999999999997 0.025000000000000001</size>
          </box>
        </geometry>
        <surface>
          <contact>
            <ode>
              <kp>10000000000000</kp>
              <kd>1</kd>
            </ode>
          </contact>
          <friction>
            <ode>
              <mu2>1</mu2>
              <fdir1>0 0 0</fdir1>
            </ode>
          </friction>
        </surface>
      </collision>
      <collision name='base_footprint_fixed_joint_lump__camera2_link_collision_2'>
        <pose>0.44496213372232862 -0.065934824203287251 0.1202908683454757 -1.3902691181408522 -0.30150558572572372 0.49610274927739545</pose>
        <geometry>
          <box>
            <size>0.025049999999999999 0.089999999999999997 0.025000000000000001</size>
          </box>
        </geometry>
        <surface>
          <contact>
            <ode>
              <kp>10000000000000</kp>
              <kd>1</kd>
            </ode>
          </contact>
          <friction>
            <ode>
              <mu2>1</mu2>
              <fdir1>0 0 0</fdir1>
            </ode>
          </friction>
        </surface>
      </collision>
      <visual name='base_footprint_fixed_joint_lump__base_link_visual'>
        <pose>-0.39000000000000001 0.27500000000000002 0.34875 0 0 0</pose>
        <geometry>
          <mesh>
            <scale>1 1 1</scale>
            <uri>model://mir_description/meshes/mir_100/visual/base.dae</uri>
          </mesh>
        </geometry>
      </visual>
      <visual name='base_footprint_fixed_joint_lump__back_laser_link_visual_1'>
        <pose>-0.38970933905932748 0.27331688245431418 0.34689999999999999 0 0 0</pose>
        <geometry>
          <mesh>
            <scale>1 1 1</scale>
            <uri>model://mir_description/meshes/mir_100/visual/SICK-lidar.dae</uri>
          </mesh>
        </geometry>
      </visual>
      <visual name='base_footprint_fixed_joint_lump__camera1_link_visual_2'>
        <pose>0.44895057545773531 0.066627910663756645 0.1200899359664465 -0.52359877559829782 1.2007963267948965 -1.0471975511965965</pose>
        <geometry>
          <mesh>
            <scale>1 1 1</scale>
            <uri>file:///opt/ros/jazzy/share/realsense2_description/meshes/d435.dae</uri>
          </mesh>
        </geometry>
      </visual>
      <visual name='base_footprint_fixed_joint_lump__camera2_link_visual_3'>
        <pose>0.44857315770130279 -0.063980347204354457 0.1215677886577568 0.5235987755982987 1.2207963267948965 1.0471975511965981</pose>
        <geometry>
          <mesh>
            <scale>1 1 1</scale>
            <uri>file:///opt/ros/jazzy/share/realsense2_description/meshes/d435.dae</uri>
          </mesh>
        </geometry>
      </visual>
      <visual name='base_footprint_fixed_joint_lump__front_laser_link_visual_4'>
        <pose>0.46500133905932739 -0.27331688245431418 0.34689999999999999 0 0 3.1415926535897931</pose>
        <geometry>
          <mesh>
            <scale>1 1 1</scale>
            <uri>model://mir_description/meshes/mir_100/visual/SICK-lidar.dae</uri>
          </mesh>
        </geometry>
      </visual>
      <sensor name='back_gpu_lidar' type='gpu_lidar'>
        <pose relative_to='back_laser_frame'>0 0 0 0 0 0</pose>
        <topic>back_laser/scan</topic>
        <update_rate>12.5</update_rate>
        <lidar>
          <scan>
            <horizontal>
              <samples>541</samples>
              <resolution>1</resolution>
              <min_angle>-2.3561944961500001</min_angle>
              <max_angle>2.3561944961500001</max_angle>
            </horizontal>
            <vertical>
              <samples>200</samples>
              <resolution>1</resolution>
              <min_angle>-0.39269910000000002</min_angle>
              <max_angle>0.39269910000000002</max_angle>
            </vertical>
          </scan>
          <range>
            <min>0.050000000000000003</min>
            <max>29</max>
            <resolution>0.01</resolution>
          </range>
          <noise>
            <type>gaussian</type>
            <mean>0</mean>
            <stddev>0.01</stddev>
          </noise>
        </lidar>
        <always_on>true</always_on>
        <visualize>true</visualize>
      </sensor>
      <self_collide>false</self_collide>
      <enable_wind>false</enable_wind>
      <kinematic>false</kinematic>
      <gravity>true</gravity>
      <sensor name='camera1color' type='camera'>
        <pose relative_to='camera1_color_frame'>0 0 0 0 0 0</pose>
        <topic>camera1/color/image</topic>
        <camera name='camera1'>
          <horizontal_fov>1.2112585008840648</horizontal_fov>
          <camera_info_topic>camera1/color/image/info</camera_info_topic>
          <image>
            <width>424</width>
            <height>240</height>
            <format>RGB_INT8</format>
          </image>
          <clip>
            <near>0.10000000000000001</near>
            <far>100</far>
          </clip>
          <noise>
            <type>gaussian</type>
            <mean>0</mean>
            <stddev>0.0070000000000000001</stddev>
          </noise>
          <segmentation_type>instance</segmentation_type>
          <box_type>2d</box_type>
          <optical_frame_id>camera1</optical_frame_id>
        </camera>
        <always_on>true</always_on>
        <update_rate>1</update_rate>
        <visualize>true</visualize>
      </sensor>
      <sensor name='camera1ired1' type='camera'>
        <pose relative_to='camera1_infra1_frame'>0 0 0 0 0 0</pose>
        <topic>camera1/infra1/image</topic>
        <camera name='camera1'>
          <horizontal_fov>1.4870205226991688</horizontal_fov>
          <camera_info_topic>camera1/infra1/image/info</camera_info_topic>
          <image>
            <width>640</width>
            <height>480</height>
            <format>L8</format>
          </image>
          <clip>
            <near>0.10000000000000001</near>
            <far>100</far>
          </clip>
          <noise>
            <type>gaussian</type>
            <mean>0</mean>
            <stddev>0.050000000000000003</stddev>
          </noise>
        </camera>
        <always_on>true</always_on>
        <update_rate>1</update_rate>
        <visualize>false</visualize>
      </sensor>
      <sensor name='camera1ired2' type='camera'>
        <pose relative_to='camera1_infra2_frame'>0 0 0 0 0 0</pose>
        <topic>camera1/infra2/image</topic>
        <camera name='camera1'>
          <horizontal_fov>1.4870205226991688</horizontal_fov>
          <camera_info_topic>camera1/infra2/image/info</camera_info_topic>
          <image>
            <width>640</width>
            <height>480</height>
            <format>L8</format>
          </image>
          <clip>
            <near>0.10000000000000001</near>
            <far>100</far>
          </clip>
          <noise>
            <type>gaussian</type>
            <mean>0</mean>
            <stddev>0.050000000000000003</stddev>
          </noise>
        </camera>
        <always_on>true</always_on>
        <update_rate>1</update_rate>
        <visualize>false</visualize>
      </sensor>
      <sensor name='camera1depth' type='depth'>
        <pose relative_to='camera1_depth_frame'>0 0 0 0 0 0</pose>
        <topic>camera1/depth/image</topic>
        <camera name='camera1'>
          <horizontal_fov>1.4870205226991688</horizontal_fov>
          <image>
            <width>320</width>
            <height>240</height>
          </image>
          <clip>
            <near>0.10000000000000001</near>
            <far>100</far>
          </clip>
          <noise>
            <type>gaussian</type>
            <mean>0</mean>
            <stddev>0.10000000000000001</stddev>
          </noise>
          <depth_camera>
            <output>depths</output>
            <clip>
              <near>0.10000000000000001</near>
              <far>100</far>
            </clip>
          </depth_camera>
        </camera>
        <always_on>true</always_on>
        <update_rate>1</update_rate>
        <visualize>false</visualize>
      </sensor>
      <self_collide>false</self_collide>
      <enable_wind>false</enable_wind>
      <kinematic>false</kinematic>
      <gravity>true</gravity>
      <sensor name='camera2color' type='camera'>
        <pose relative_to='camera2_color_frame'>0 0 0 0 0 0</pose>
        <topic>camera2/color/image</topic>
        <camera name='camera2'>
          <horizontal_fov>1.2112585008840648</horizontal_fov>
          <camera_info_topic>camera2/color/image/info</camera_info_topic>
          <image>
            <width>424</width>
            <height>240</height>
            <format>RGB_INT8</format>
          </image>
          <clip>
            <near>0.10000000000000001</near>
            <far>100</far>
          </clip>
          <noise>
            <type>gaussian</type>
            <mean>0</mean>
            <stddev>0.0070000000000000001</stddev>
          </noise>
          <segmentation_type>instance</segmentation_type>
          <box_type>2d</box_type>
          <optical_frame_id>camera2</optical_frame_id>
        </camera>
        <always_on>true</always_on>
        <update_rate>1</update_rate>
        <visualize>true</visualize>
      </sensor>
      <sensor name='camera2ired1' type='camera'>
        <pose relative_to='camera2_infra1_frame'>0 0 0 0 0 0</pose>
        <topic>camera2/infra1/image</topic>
        <camera name='camera2'>
          <horizontal_fov>1.4870205226991688</horizontal_fov>
          <camera_info_topic>camera2/infra1/image/info</camera_info_topic>
          <image>
            <width>640</width>
            <height>480</height>
            <format>L8</format>
          </image>
          <clip>
            <near>0.10000000000000001</near>
            <far>100</far>
          </clip>
          <noise>
            <type>gaussian</type>
            <mean>0</mean>
            <stddev>0.050000000000000003</stddev>
          </noise>
        </camera>
        <always_on>true</always_on>
        <update_rate>1</update_rate>
        <visualize>false</visualize>
      </sensor>
      <sensor name='camera2ired2' type='camera'>
        <pose relative_to='camera2_infra2_frame'>0 0 0 0 0 0</pose>
        <topic>camera2/infra2/image</topic>
        <camera name='camera2'>
          <horizontal_fov>1.4870205226991688</horizontal_fov>
          <camera_info_topic>camera2/infra2/image/info</camera_info_topic>
          <image>
            <width>640</width>
            <height>480</height>
            <format>L8</format>
          </image>
          <clip>
            <near>0.10000000000000001</near>
            <far>100</far>
          </clip>
          <noise>
            <type>gaussian</type>
            <mean>0</mean>
            <stddev>0.050000000000000003</stddev>
          </noise>
        </camera>
        <always_on>true</always_on>
        <update_rate>1</update_rate>
        <visualize>false</visualize>
      </sensor>
      <sensor name='camera2depth' type='depth'>
        <pose relative_to='camera2_depth_frame'>0 0 0 0 0 0</pose>
        <topic>camera2/depth/image</topic>
        <camera name='camera2'>
          <horizontal_fov>1.4870205226991688</horizontal_fov>
          <image>
            <width>320</width>
            <height>240</height>
          </image>
          <clip>
            <near>0.10000000000000001</near>
            <far>100</far>
          </clip>
          <noise>
            <type>gaussian</type>
            <mean>0</mean>
            <stddev>0.10000000000000001</stddev>
          </noise>
          <depth_camera>
            <output>depths</output>
            <clip>
              <near>0.10000000000000001</near>
              <far>100</far>
            </clip>
          </depth_camera>
        </camera>
        <always_on>true</always_on>
        <update_rate>1</update_rate>
        <visualize>false</visualize>
      </sensor>
      <sensor name='front_gpu_lidar' type='gpu_lidar'>
        <pose relative_to='front_laser_frame'>0 0 0 0 0 0</pose>
        <topic>front_laser/scan</topic>
        <update_rate>12.5</update_rate>
        <lidar>
          <scan>
            <horizontal>
              <samples>541</samples>
              <resolution>1</resolution>
              <min_angle>-2.3561944961500001</min_angle>
              <max_angle>2.3561944961500001</max_angle>
            </horizontal>
            <vertical>
              <samples>200</samples>
              <resolution>1</resolution>
              <min_angle>-0.39269910000000002</min_angle>
              <max_angle>0.39269910000000002</max_angle>
            </vertical>
          </scan>
          <range>
            <min>0.050000000000000003</min>
            <max>29</max>
            <resolution>0.01</resolution>
          </range>
          <noise>
            <type>gaussian</type>
            <mean>0</mean>
            <stddev>0.01</stddev>
          </noise>
        </lidar>
        <always_on>true</always_on>
        <visualize>true</visualize>
      </sensor>
      <sensor name='imu_sensor' type='imu'>
        <always_on>true</always_on>
        <update_rate>41</update_rate>
        <visualize>true</visualize>
        <topic>imu</topic>
        <imu>
          <enable_orientation>true</enable_orientation>
          <angular_velocity>
            <x>
              <noise type='gaussian'>
                <mean>0</mean>
                <stddev>0.0028279999999999998</stddev>
                <bias_mean>0</bias_mean>
                <bias_stddev>0.007071</bias_stddev>
                <dynamic_bias_stddev>2.0000000000000002e-05</dynamic_bias_stddev>
                <dynamic_bias_correlation_time>400</dynamic_bias_correlation_time>
              </noise>
            </x>
            <y>
              <noise type='gaussian'>
                <mean>0</mean>
                <stddev>0.0089999999999999993</stddev>
                <bias_mean>0.0028279999999999998</bias_mean>
                <bias_stddev>0.0050000000000000001</bias_stddev>
                <dynamic_bias_stddev>2.0000000000000002e-05</dynamic_bias_stddev>
                <dynamic_bias_correlation_time>400</dynamic_bias_correlation_time>
              </noise>
            </y>
            <z>
              <noise type='gaussian'>
                <mean>0</mean>
                <stddev>0.0089999999999999993</stddev>
                <bias_mean>0.00054699999999999996</bias_mean>
                <bias_stddev>0.0050000000000000001</bias_stddev>
                <dynamic_bias_stddev>2.0000000000000002e-05</dynamic_bias_stddev>
                <dynamic_bias_correlation_time>400</dynamic_bias_correlation_time>
              </noise>
            </z>
          </angular_velocity>
          <linear_acceleration>
            <x>
              <noise type='gaussian'>
                <mean>0</mean>
                <stddev>0.007071</stddev>
                <bias_mean>0.050000000000000003</bias_mean>
                <bias_stddev>0.0074999999999999997</bias_stddev>
                <dynamic_bias_stddev>0.00037500000000000001</dynamic_bias_stddev>
                <dynamic_bias_correlation_time>175</dynamic_bias_correlation_time>
              </noise>
            </x>
            <y>
              <noise type='gaussian'>
                <mean>0</mean>
                <stddev>0.01</stddev>
                <bias_mean>0.050000000000000003</bias_mean>
                <bias_stddev>0.0074999999999999997</bias_stddev>
                <dynamic_bias_stddev>0.00037500000000000001</dynamic_bias_stddev>
                <dynamic_bias_correlation_time>175</dynamic_bias_correlation_time>
              </noise>
            </y>
            <z>
              <noise type='gaussian'>
                <mean>0</mean>
                <stddev>0.011401</stddev>
                <bias_mean>0.050000000000000003</bias_mean>
                <bias_stddev>0.0074999999999999997</bias_stddev>
                <dynamic_bias_stddev>0.00037500000000000001</dynamic_bias_stddev>
                <dynamic_bias_correlation_time>175</dynamic_bias_correlation_time>
              </noise>
            </z>
          </linear_acceleration>
        </imu>
        <pose>0 0 0.25 0 0 0</pose>
      </sensor>
    </link>
    <joint name='bl_caster_rotation_joint' type='revolute'>
      <pose relative_to='base_footprint'>-0.27015400000000001 0.20300000000000001 0.1565 0 0 0</pose>
      <parent>base_footprint</parent>
      <child>bl_caster_rotation_link</child>
      <axis>
        <xyz>0 0 1</xyz>
        <limit>
          <lower>-inf</lower>
          <upper>inf</upper>
        </limit>
        <dynamics>
          <damping>0.01</damping>
          <friction>0</friction>
          <spring_reference>0</spring_reference>
          <spring_stiffness>0</spring_stiffness>
        </dynamics>
      </axis>
    </joint>
    <link name='bl_caster_rotation_link'>
      <pose relative_to='bl_caster_rotation_joint'>0 0 0 0 0 0</pose>
      <inertial>
        <pose>0 0 -0.042500000044000001 0.41887902047863912 -2.7755575615628914e-17 1.5707963267948972</pose>
        <mass>0.30975390190000002</mass>
        <inertia>
          <ixx>0.00058445179780000005</ixx>
          <ixy>0</ixy>
          <ixz>0</ixz>
          <iyy>0.00052872551237000001</iyy>
          <iyz>0</iyz>
          <izz>0.00017923555073999999</izz>
        </inertia>
      </inertial>
      <visual name='bl_caster_rotation_link_visual'>
        <pose>-0.12 0.070000000000000007 0.20200000000000001 0 0 0</pose>
        <geometry>
          <mesh>
            <scale>1 1 1</scale>
            <uri>model://mir_description/meshes/mir_100/visual/caster-wheel-base.dae</uri>
          </mesh>
        </geometry>
      </visual>
    </link>
    <joint name='bl_caster_wheel_joint' type='revolute'>
      <pose relative_to='bl_caster_rotation_link'>-0.038199999999999998 0 -0.094 0 0 0</pose>
      <parent>bl_caster_rotation_link</parent>
      <child>bl_caster_wheel_link</child>
      <axis>
        <xyz>0 1 0</xyz>
        <limit>
          <lower>-inf</lower>
          <upper>inf</upper>
        </limit>
        <dynamics>
          <spring_reference>0</spring_reference>
          <spring_stiffness>0</spring_stiffness>
        </dynamics>
      </axis>
    </joint>
    <link name='bl_caster_wheel_link'>
      <pose relative_to='bl_caster_wheel_joint'>0 0 0 0 0 0</pose>
      <inertial>
        <pose>0 0 0 1.5707963267948959 0 0</pose>
        <mass>1</mass>
        <inertia>
          <ixx>0.001061895408575</ixx>
          <ixy>0</ixy>
          <ixz>0</ixz>
          <iyy>0.001061895408575</iyy>
          <iyz>0</iyz>
          <izz>0.001953125</izz>
        </inertia>
      </inertial>
      <collision name='bl_caster_wheel_link_collision'>
        <pose>0 0 0 1.5707963267948959 0 0</pose>
        <geometry>
          <cylinder>
            <length>0.032000000000000001</length>
            <radius>0.0625</radius>
          </cylinder>
        </geometry>
        <surface>
          <contact>
            <ode>
              <kp>10000000</kp>
              <kd>1</kd>
              <min_depth>0.01</min_depth>
            </ode>
          </contact>
          <friction>
            <ode>
              <mu>1</mu>
              <mu2>1</mu2>
            </ode>
          </friction>
        </surface>
      </collision>
      <visual name='bl_caster_wheel_link_visual'>
        <pose>-0.082000000000000003 0.47999999999999998 0.28749999999999998 0 0 0</pose>
        <geometry>
          <mesh>
            <scale>1 1 1</scale>
            <uri>model://mir_description/meshes/mir_100/visual/caster-wheel.dae</uri>
          </mesh>
        </geometry>
      </visual>
    </link>
    <joint name='br_caster_rotation_joint' type='revolute'>
      <pose relative_to='base_footprint'>-0.27015400000000001 -0.20300000000000001 0.1565 0 0 0</pose>
      <parent>base_footprint</parent>
      <child>br_caster_rotation_link</child>
      <axis>
        <xyz>0 0 1</xyz>
        <limit>
          <lower>-inf</lower>
          <upper>inf</upper>
        </limit>
        <dynamics>
          <damping>0.01</damping>
          <friction>0</friction>
          <spring_reference>0</spring_reference>
          <spring_stiffness>0</spring_stiffness>
        </dynamics>
      </axis>
    </joint>
    <link name='br_caster_rotation_link'>
      <pose relative_to='br_caster_rotation_joint'>0 0 0 0 0 0</pose>
      <inertial>
        <pose>0 0 -0.042500000044000001 0.41887902047863912 -2.7755575615628914e-17 1.5707963267948972</pose>
        <mass>0.30975390190000002</mass>
        <inertia>
          <ixx>0.00058445179780000005</ixx>
          <ixy>0</ixy>
          <ixz>0</ixz>
          <iyy>0.00052872551237000001</iyy>
          <iyz>0</iyz>
          <izz>0.00017923555073999999</izz>
        </inertia>
      </inertial>
      <visual name='br_caster_rotation_link_visual'>
        <pose>-0.12 0.070000000000000007 0.20200000000000001 0 0 0</pose>
        <geometry>
          <mesh>
            <scale>1 1 1</scale>
            <uri>model://mir_description/meshes/mir_100/visual/caster-wheel-base.dae</uri>
          </mesh>
        </geometry>
      </visual>
    </link>
    <joint name='br_caster_wheel_joint' type='revolute'>
      <pose relative_to='br_caster_rotation_link'>-0.038199999999999998 0 -0.094 0 0 0</pose>
      <parent>br_caster_rotation_link</parent>
      <child>br_caster_wheel_link</child>
      <axis>
        <xyz>0 1 0</xyz>
        <limit>
          <lower>-inf</lower>
          <upper>inf</upper>
        </limit>
        <dynamics>
          <spring_reference>0</spring_reference>
          <spring_stiffness>0</spring_stiffness>
        </dynamics>
      </axis>
    </joint>
    <link name='br_caster_wheel_link'>
      <pose relative_to='br_caster_wheel_joint'>0 0 0 0 0 0</pose>
      <inertial>
        <pose>0 0 0 1.5707963267948959 0 0</pose>
        <mass>1</mass>
        <inertia>
          <ixx>0.001061895408575</ixx>
          <ixy>0</ixy>
          <ixz>0</ixz>
          <iyy>0.001061895408575</iyy>
          <iyz>0</iyz>
          <izz>0.001953125</izz>
        </inertia>
      </inertial>
      <collision name='br_caster_wheel_link_collision'>
        <pose>0 0 0 1.5707963267948959 0 0</pose>
        <geometry>
          <cylinder>
            <length>0.032000000000000001</length>
            <radius>0.0625</radius>
          </cylinder>
        </geometry>
        <surface>
          <contact>
            <ode>
              <kp>10000000</kp>
              <kd>1</kd>
              <min_depth>0.01</min_depth>
            </ode>
          </contact>
          <friction>
            <ode>
              <mu>1</mu>
              <mu2>1</mu2>
            </ode>
          </friction>
        </surface>
      </collision>
      <visual name='br_caster_wheel_link_visual'>
        <pose>-0.082000000000000003 0.47999999999999998 0.28749999999999998 0 0 0</pose>
        <geometry>
          <mesh>
            <scale>1 1 1</scale>
            <uri>model://mir_description/meshes/mir_100/visual/caster-wheel.dae</uri>
          </mesh>
        </geometry>
      </visual>
    </link>
    <joint name='fl_caster_rotation_joint' type='revolute'>
      <pose relative_to='base_footprint'>0.34134599999999998 0.20300000000000001 0.1565 0 0 0</pose>
      <parent>base_footprint</parent>
      <child>fl_caster_rotation_link</child>
      <axis>
        <xyz>0 0 1</xyz>
        <limit>
          <lower>-inf</lower>
          <upper>inf</upper>
        </limit>
        <dynamics>
          <damping>0.01</damping>
          <friction>0</friction>
          <spring_reference>0</spring_reference>
          <spring_stiffness>0</spring_stiffness>
        </dynamics>
      </axis>
    </joint>
    <link name='fl_caster_rotation_link'>
      <pose relative_to='fl_caster_rotation_joint'>0 0 0 0 0 0</pose>
      <inertial>
        <pose>0 0 -0.042500000044000001 0.41887902047863912 -2.7755575615628914e-17 1.5707963267948972</pose>
        <mass>0.30975390190000002</mass>
        <inertia>
          <ixx>0.00058445179780000005</ixx>
          <ixy>0</ixy>
          <ixz>0</ixz>
          <iyy>0.00052872551237000001</iyy>
          <iyz>0</iyz>
          <izz>0.00017923555073999999</izz>
        </inertia>
      </inertial>
      <visual name='fl_caster_rotation_link_visual'>
        <pose>-0.12 0.070000000000000007 0.20200000000000001 0 0 0</pose>
        <geometry>
          <mesh>
            <scale>1 1 1</scale>
            <uri>model://mir_description/meshes/mir_100/visual/caster-wheel-base.dae</uri>
          </mesh>
        </geometry>
      </visual>
    </link>
    <joint name='fl_caster_wheel_joint' type='revolute'>
      <pose relative_to='fl_caster_rotation_link'>-0.038199999999999998 0 -0.094 0 0 0</pose>
      <parent>fl_caster_rotation_link</parent>
      <child>fl_caster_wheel_link</child>
      <axis>
        <xyz>0 1 0</xyz>
        <limit>
          <lower>-inf</lower>
          <upper>inf</upper>
        </limit>
        <dynamics>
          <spring_reference>0</spring_reference>
          <spring_stiffness>0</spring_stiffness>
        </dynamics>
      </axis>
    </joint>
    <link name='fl_caster_wheel_link'>
      <pose relative_to='fl_caster_wheel_joint'>0 0 0 0 0 0</pose>
      <inertial>
        <pose>0 0 0 1.5707963267948959 0 0</pose>
        <mass>1</mass>
        <inertia>
          <ixx>0.001061895408575</ixx>
          <ixy>0</ixy>
          <ixz>0</ixz>
          <iyy>0.001061895408575</iyy>
          <iyz>0</iyz>
          <izz>0.001953125</izz>
        </inertia>
      </inertial>
      <collision name='fl_caster_wheel_link_collision'>
        <pose>0 0 0 1.5707963267948959 0 0</pose>
        <geometry>
          <cylinder>
            <length>0.032000000000000001</length>
            <radius>0.0625</radius>
          </cylinder>
        </geometry>
        <surface>
          <contact>
            <ode>
              <kp>10000000</kp>
              <kd>1</kd>
              <min_depth>0.01</min_depth>
            </ode>
          </contact>
          <friction>
            <ode>
              <mu>1</mu>
              <mu2>1</mu2>
            </ode>
          </friction>
        </surface>
      </collision>
      <visual name='fl_caster_wheel_link_visual'>
        <pose>-0.082000000000000003 0.47999999999999998 0.28749999999999998 0 0 0</pose>
        <geometry>
          <mesh>
            <scale>1 1 1</scale>
            <uri>model://mir_description/meshes/mir_100/visual/caster-wheel.dae</uri>
          </mesh>
        </geometry>
      </visual>
    </link>
    <joint name='fr_caster_rotation_joint' type='revolute'>
      <pose relative_to='base_footprint'>0.34134599999999998 -0.20300000000000001 0.1565 0 0 0</pose>
      <parent>base_footprint</parent>
      <child>fr_caster_rotation_link</child>
      <axis>
        <xyz>0 0 1</xyz>
        <limit>
          <lower>-inf</lower>
          <upper>inf</upper>
        </limit>
        <dynamics>
          <damping>0.01</damping>
          <friction>0</friction>
          <spring_reference>0</spring_reference>
          <spring_stiffness>0</spring_stiffness>
        </dynamics>
      </axis>
    </joint>
    <link name='fr_caster_rotation_link'>
      <pose relative_to='fr_caster_rotation_joint'>0 0 0 0 0 0</pose>
      <inertial>
        <pose>0 0 -0.042500000044000001 0.41887902047863912 -2.7755575615628914e-17 1.5707963267948972</pose>
        <mass>0.30975390190000002</mass>
        <inertia>
          <ixx>0.00058445179780000005</ixx>
          <ixy>0</ixy>
          <ixz>0</ixz>
          <iyy>0.00052872551237000001</iyy>
          <iyz>0</iyz>
          <izz>0.00017923555073999999</izz>
        </inertia>
      </inertial>
      <visual name='fr_caster_rotation_link_visual'>
        <pose>-0.12 0.070000000000000007 0.20200000000000001 0 0 0</pose>
        <geometry>
          <mesh>
            <scale>1 1 1</scale>
            <uri>model://mir_description/meshes/mir_100/visual/caster-wheel-base.dae</uri>
          </mesh>
        </geometry>
      </visual>
    </link>
    <joint name='fr_caster_wheel_joint' type='revolute'>
      <pose relative_to='fr_caster_rotation_link'>-0.038199999999999998 0 -0.094 0 0 0</pose>
      <parent>fr_caster_rotation_link</parent>
      <child>fr_caster_wheel_link</child>
      <axis>
        <xyz>0 1 0</xyz>
        <limit>
          <lower>-inf</lower>
          <upper>inf</upper>
        </limit>
        <dynamics>
          <spring_reference>0</spring_reference>
          <spring_stiffness>0</spring_stiffness>
        </dynamics>
      </axis>
    </joint>
    <link name='fr_caster_wheel_link'>
      <pose relative_to='fr_caster_wheel_joint'>0 0 0 0 0 0</pose>
      <inertial>
        <pose>0 0 0 1.5707963267948959 0 0</pose>
        <mass>1</mass>
        <inertia>
          <ixx>0.001061895408575</ixx>
          <ixy>0</ixy>
          <ixz>0</ixz>
          <iyy>0.001061895408575</iyy>
          <iyz>0</iyz>
          <izz>0.001953125</izz>
        </inertia>
      </inertial>
      <collision name='fr_caster_wheel_link_collision'>
        <pose>0 0 0 1.5707963267948959 0 0</pose>
        <geometry>
          <cylinder>
            <length>0.032000000000000001</length>
            <radius>0.0625</radius>
          </cylinder>
        </geometry>
        <surface>
          <contact>
            <ode>
              <kp>10000000</kp>
              <kd>1</kd>
              <min_depth>0.01</min_depth>
            </ode>
          </contact>
          <friction>
            <ode>
              <mu>1</mu>
              <mu2>1</mu2>
            </ode>
          </friction>
        </surface>
      </collision>
      <visual name='fr_caster_wheel_link_visual'>
        <pose>-0.082000000000000003 0.47999999999999998 0.28749999999999998 0 0 0</pose>
        <geometry>
          <mesh>
            <scale>1 1 1</scale>
            <uri>model://mir_description/meshes/mir_100/visual/caster-wheel.dae</uri>
          </mesh>
        </geometry>
      </visual>
    </link>
    <joint name='left_wheel_joint' type='revolute'>
      <pose relative_to='base_footprint'>0 0.222604 0.0625 0 0 0</pose>
      <parent>base_footprint</parent>
      <child>left_wheel_link</child>
      <axis>
        <xyz>0 1 0</xyz>
        <limit>
          <effort>100</effort>
          <velocity>20</velocity>
          <lower>-inf</lower>
          <upper>inf</upper>
        </limit>
        <dynamics>
          <spring_reference>0</spring_reference>
          <spring_stiffness>0</spring_stiffness>
        </dynamics>
      </axis>
    </joint>
    <link name='left_wheel_link'>
      <pose relative_to='left_wheel_joint'>0 0 0 0 0 0</pose>
      <inertial>
        <pose>0 0 0 1.5707963267948959 0 0</pose>
        <mass>1</mass>
        <inertia>
          <ixx>0.001061895408575</ixx>
          <ixy>0</ixy>
          <ixz>0</ixz>
          <iyy>0.001061895408575</iyy>
          <iyz>0</iyz>
          <izz>0.001953125</izz>
        </inertia>
      </inertial>
      <collision name='left_wheel_link_collision'>
        <pose>0 0 0 1.5707963267948959 0 0</pose>
        <geometry>
          <cylinder>
            <length>0.032000000000000001</length>
            <radius>0.0625</radius>
          </cylinder>
        </geometry>
        <surface>
          <contact>
            <ode>
              <kp>10000000</kp>
              <kd>1</kd>
              <min_depth>0.01</min_depth>
            </ode>
          </contact>
          <friction>
            <ode>
              <mu>200</mu>
              <mu2>200</mu2>
            </ode>
          </friction>
        </surface>
      </collision>
      <visual name='left_wheel_link_visual'>
        <pose>-0.026200000000000001 -0.42958299999999999 0.42299999999999999 0 0 -3.1415926535897931</pose>
        <geometry>
          <mesh>
            <scale>1 1 1</scale>
            <uri>model://mir_description/meshes/mir_100/visual/wheel.dae</uri>
          </mesh>
        </geometry>
      </visual>
    </link>
    <joint name='right_wheel_joint' type='revolute'>
      <pose relative_to='base_footprint'>0 -0.222604 0.0625 0 0 0</pose>
      <parent>base_footprint</parent>
      <child>right_wheel_link</child>
      <axis>
        <xyz>0 1 0</xyz>
        <limit>
          <effort>100</effort>
          <velocity>20</velocity>
          <lower>-inf</lower>
          <upper>inf</upper>
        </limit>
        <dynamics>
          <spring_reference>0</spring_reference>
          <spring_stiffness>0</spring_stiffness>
        </dynamics>
      </axis>
    </joint>
    <link name='right_wheel_link'>
      <pose relative_to='right_wheel_joint'>0 0 0 0 0 0</pose>
      <inertial>
        <pose>0 0 0 1.5707963267948959 0 0</pose>
        <mass>1</mass>
        <inertia>
          <ixx>0.001061895408575</ixx>
          <ixy>0</ixy>
          <ixz>0</ixz>
          <iyy>0.001061895408575</iyy>
          <iyz>0</iyz>
          <izz>0.001953125</izz>
        </inertia>
      </inertial>
      <collision name='right_wheel_link_collision'>
        <pose>0 0 0 1.5707963267948959 0 0</pose>
        <geometry>
          <cylinder>
            <length>0.032000000000000001</length>
            <radius>0.0625</radius>
          </cylinder>
        </geometry>
        <surface>
          <contact>
            <ode>
              <kp>10000000</kp>
              <kd>1</kd>
              <min_depth>0.01</min_depth>
            </ode>
          </contact>
          <friction>
            <ode>
              <mu>200</mu>
              <mu2>200</mu2>
            </ode>
          </friction>
        </surface>
      </collision>
      <visual name='right_wheel_link_visual'>
        <pose>0.026200000000000001 0.42958299999999999 0.42299999999999999 0 0 0</pose>
        <geometry>
          <mesh>
            <scale>1 1 1</scale>
            <uri>model://mir_description/meshes/mir_100/visual/wheel.dae</uri>
          </mesh>
        </geometry>
      </visual>
    </link>
    <plugin name='gz_ros2_control::GazeboSimROS2ControlPlugin' filename='gz_ros2_control-system'>
      <parameters>/home/ubuntu/workspace/install/mir_gazebo/share/mir_gazebo/config/diff_drive_controller_velocity.yaml</parameters>
      <controller_manager_name>mir_controller_manager</controller_manager_name>
      <ros>
        <namespace/>
        <remapping>/robot_description:=/robot_description</remapping>
      </ros>
    </plugin>
    <plugin name='gz::sim::systems::Sensors' filename='gz-sim-sensors-system'>
      <frame_id>custom_params/link</frame_id>
      <render_engine>ogre2</render_engine>
    </plugin>
    <plugin name='gz::sim::systems::Imu' filename='gz-sim-imu-system'/>
    <frame name='base_link_surface_joint' attached_to='base_link'>
      <pose>0.037645999999999999 0 0.35199999999999998 0 0 0</pose>
    </frame>
    <frame name='surface' attached_to='base_link_surface_joint'>
      <pose>0 0 0 0 0 0</pose>
    </frame>
    <frame name='back_laser_link_to_back_laser_frame_joint' attached_to='back_laser_link'>
      <pose>0 0 0 0 0 0</pose>
    </frame>
    <frame name='back_laser_frame' attached_to='back_laser_link_to_back_laser_frame_joint'>
      <pose>0 0 0 0 0 0</pose>
    </frame>
    <frame name='base_link_to_back_laser_joint' attached_to='base_link'>
      <pose>-0.354354 -0.23580000000000001 0.19139999999999999 0 0 -2.3561944901923448</pose>
    </frame>
    <frame name='back_laser_link' attached_to='base_link_to_back_laser_joint'>
      <pose>0 0 0 0 0 0</pose>
    </frame>
    <frame name='camera1_link_joint' attached_to='camera1_bottom_screw_frame'>
      <pose>0.0106 0.017500000000000002 0.012500000000000001 0 0 0</pose>
    </frame>
    <frame name='camera1_link' attached_to='camera1_link_joint'>
      <pose>0 0 0 0 0 0</pose>
    </frame>
    <frame name='camera1_joint' attached_to='camera_1_link'>
      <pose>0.01 0.001 -0.02 0 -0.52359877559829882 0</pose>
    </frame>
    <frame name='camera1_bottom_screw_frame' attached_to='camera1_joint'>
      <pose>0 0 0 0 0 0</pose>
    </frame>
    <frame name='charge_point_link_to_camera1' attached_to='charge_point_link'>
      <pose>-0.025000000000000001 0.081250000000000003 -0.014999999999999999 -1.5707963267948957 -0.37000000000000016 -1.047197551196597</pose>
    </frame>
    <frame name='camera_1_link' attached_to='charge_point_link_to_camera1'>
      <pose>0 0 0 0 0 0</pose>
    </frame>
    <frame name='camera2_link_joint' attached_to='camera2_bottom_screw_frame'>
      <pose>0.0106 0.017500000000000002 0.012500000000000001 0 0 0</pose>
    </frame>
    <frame name='camera2_link' attached_to='camera2_link_joint'>
      <pose>0 0 0 0 0 0</pose>
    </frame>
    <frame name='camera2_joint' attached_to='camera_2_link'>
      <pose>0 0 0 0 0.52359877559829882 0</pose>
    </frame>
    <frame name='camera2_bottom_screw_frame' attached_to='camera2_joint'>
      <pose>0 0 0 0 0 0</pose>
    </frame>
    <frame name='charge_point_link_to_camera2' attached_to='charge_point_link'>
      <pose>-0.025000000000000001 -0.081250000000000003 -0.014999999999999999 -1.5707963267948959 -0.35000000000000003 1.0471975511965979</pose>
    </frame>
    <frame name='camera_2_link' attached_to='charge_point_link_to_camera2'>
      <pose>0 0 0 0 0 0</pose>
    </frame>
    <frame name='base_link_to_charging_link' attached_to='base_link'>
      <pose>0.46750000000000003 0 0.13 0 0 0</pose>
    </frame>
    <frame name='charge_point_link' attached_to='base_link_to_charging_link'>
      <pose>0 0 0 0 0 0</pose>
    </frame>
    <frame name='front_laser_link_to_front_laser_frame_joint' attached_to='front_laser_link'>
      <pose>0 0 0 0 0 0</pose>
    </frame>
    <frame name='front_laser_frame' attached_to='front_laser_link_to_front_laser_frame_joint'>
      <pose>0 0 0 0 0 0</pose>
    </frame>
    <frame name='base_link_to_front_laser_joint' attached_to='base_link'>
      <pose>0.42964599999999997 0.23580000000000001 0.19139999999999999 0 0 0.78539816339744839</pose>
    </frame>
    <frame name='front_laser_link' attached_to='base_link_to_front_laser_joint'>
      <pose>0 0 0 0 0 0</pose>
    </frame>
    <frame name='imu_link_to_imu_frame_joint' attached_to='imu_link'>
      <pose>0 0 0 0 0 0</pose>
    </frame>
    <frame name='imu_frame' attached_to='imu_link_to_imu_frame_joint'>
      <pose>0 0 0 0 0 0</pose>
    </frame>
    <frame name='base_link_to_imu_joint' attached_to='base_link'>
      <pose>0 0 0.25 0 0 0</pose>
    </frame>
    <frame name='imu_link' attached_to='base_link_to_imu_joint'>
      <pose>0 0 0 0 0 0</pose>
    </frame>
    <frame name='us_1_joint' attached_to='base_link'>
      <pose>0.45000000000000001 -0.12 0.16 0 0 0</pose>
    </frame>
    <frame name='us_1_frame' attached_to='us_1_joint'>
      <pose>0 0 0 0 0 0</pose>
    </frame>
    <frame name='us_2_joint' attached_to='base_link'>
      <pose>0.45000000000000001 0.12 0.16 0 0 0</pose>
    </frame>
    <frame name='us_2_frame' attached_to='us_2_joint'>
      <pose>0 0 0 0 0 0</pose>
    </frame>
    <frame name='base_joint' attached_to='base_footprint'>
      <pose>0 0 0 0 0 0</pose>
    </frame>
    <frame name='base_link' attached_to='base_joint'>
      <pose>0 0 0 0 0 0</pose>
    </frame>
  </model>
</sdf>
